import { validateConfig } from './config';
import { TaskLoggerBot } from './bot';
import { Scheduler } from './scheduler';

/**
 * アプリケーションのメインエントリーポイント
 * Discord Task Logger の起動と初期化を行う
 */
class Application {
  private bot: TaskLoggerBot;
  private scheduler: Scheduler;

  constructor() {
    this.bot = new TaskLoggerBot();
    this.scheduler = new Scheduler(this.bot);
  }

  /**
   * アプリケーションを起動
   */
  public async start(): Promise<void> {
    try {
      console.log('🚀 Discord Task Logger を起動しています...\n');
      
      // 設定の検証
      validateConfig();
      console.log('');
      
      // Discord Bot の起動
      await this.bot.start();
      console.log('');
      
      // スケジューラーの開始
      await this.scheduler.start();
      console.log('');
      
      console.log('🎉 Discord Task Logger が正常に起動しました！');
      console.log('📝 タスクの記録を開始します...\n');
      
      // 終了処理の設定
      this.setupGracefulShutdown();
      
    } catch (error) {
      console.error('❌ アプリケーションの起動に失敗しました:', error);
      process.exit(1);
    }
  }

  /**
   * アプリケーションを停止
   */
  public async stop(): Promise<void> {
    try {
      console.log('\n🛑 Discord Task Logger を停止しています...');
      
      // スケジューラーの停止
      this.scheduler.stop();
      
      // Discord Bot の停止
      await this.bot.stop();
      
      console.log('✅ Discord Task Logger が正常に停止しました');
      
    } catch (error) {
      console.error('❌ アプリケーションの停止中にエラーが発生しました:', error);
    }
  }

  /**
   * グレースフルシャットダウンの設定
   * Ctrl+C や SIGTERM でアプリケーションを適切に終了する
   */
  private setupGracefulShutdown(): void {
    // プロセス終了シグナルをキャッチ
    const signals = ['SIGINT', 'SIGTERM', 'SIGQUIT'];
    
    signals.forEach(signal => {
      process.on(signal, async () => {
        console.log(`\n📡 ${signal} シグナルを受信しました`);
        await this.stop();
        process.exit(0);
      });
    });

    // 未捕捉エラーの処理
    process.on('unhandledRejection', (reason, promise) => {
      console.error('❌ 未処理のPromise拒否:', reason);
      console.error('Promise:', promise);
    });

    process.on('uncaughtException', (error) => {
      console.error('❌ 未捕捉の例外:', error);
      this.stop().finally(() => {
        process.exit(1);
      });
    });
  }
}

// アプリケーションの実行
const app = new Application();
app.start().catch((error) => {
  console.error('❌ アプリケーション起動エラー:', error);
  process.exit(1);
});